Workbook

Sheet Bitcoin
A1: =IFERROR(__xludf.DUMMYFUNCTION("GOOGLEFINANCE(""CURRENCY:BTCINR"", ""price"", DATE(2025,7,28), DATE(2026,7,28), ""DAILY"")"),"Date") -> Date | B1: =IFERROR(__xludf.DUMMYFUNCTION("""COMPUTED_VALUE"""),"Close") -> Close
A2: =IFERROR(__xludf.DUMMYFUNCTION("""COMPUTED_VALUE"""),45866.99861111111) -> 45866.999 | B2: =IFERROR(__xludf.DUMMYFUNCTION("""COMPUTED_VALUE"""),1.03511532E7) -> 10351153
A3: =IFERROR(__xludf.DUMMYFUNCTION("""COMPUTED_VALUE"""),45867.99861111111) -> 45867.999 | B3: =IFERROR(__xludf.DUMMYFUNCTION("""COMPUTED_VALUE"""),1.033937314E7) -> 10339373
A4: =IFERROR(__xludf.DUMMYFUNCTION("""COMPUTED_VALUE"""),45868.99861111111) -> 45868.999 | B4: =IFERROR(__xludf.DUMMYFUNCTION("""COMPUTED_VALUE"""),1.036577811E7) -> 10365778
A5: =IFERROR(__xludf.DUMMYFUNCTION("""COMPUTED_VALUE"""),45869.99861111111) -> 45869.999 | B5: =IFERROR(__xludf.DUMMYFUNCTION("""COMPUTED_VALUE"""),1.036350438E7) -> 10363504
A6: =IFERROR(__xludf.DUMMYFUNCTION("""COMPUTED_VALUE"""),45870.99861111111) -> 45870.999 | B6: =IFERROR(__xludf.DUMMYFUNCTION("""COMPUTED_VALUE"""),1.007678955E7) -> 10076790
A7: =IFERROR(__xludf.DUMMYFUNCTION("""COMPUTED_VALUE"""),45871.99861111111) -> 45871.999 | B7: =IFERROR(__xludf.DUMMYFUNCTION("""COMPUTED_VALUE"""),9926081.473) -> 9926081.5
A8: =IFERROR(__xludf.DUMMYFUNCTION("""COMPUTED_VALUE"""),45872.99861111111) -> 45872.999 | B8: =IFERROR(__xludf.DUMMYFUNCTION("""COMPUTED_VALUE"""),9922460.316) -> 9922460.3
A9: =IFERROR(__xludf.DUMMYFUNCTION("""COMPUTED_VALUE"""),45873.99861111111) -> 45873.999 | B9: =IFERROR(__xludf.DUMMYFUNCTION("""COMPUTED_VALUE"""),1.008101872E7) -> 10081019
A10: =IFERROR(__xludf.DUMMYFUNCTION("""COMPUTED_VALUE"""),45874.99861111111) -> 45874.999 | B10: =IFERROR(__xludf.DUMMYFUNCTION("""COMPUTED_VALUE"""),1.003097858E7) -> 10030979
A11: =IFERROR(__xludf.DUMMYFUNCTION("""COMPUTED_VALUE"""),45875.99861111111) -> 45875.999 | B11: =IFERROR(__xludf.DUMMYFUNCTION("""COMPUTED_VALUE"""),9967617.161) -> 9967617.2
A12: =IFERROR(__xludf.DUMMYFUNCTION("""COMPUTED_VALUE"""),45876.99861111111) -> 45876.999 | B12: =IFERROR(__xludf.DUMMYFUNCTION("""COMPUTED_VALUE"""),1.000980738E7) -> 10009807
A13: =IFERROR(__xludf.DUMMYFUNCTION("""COMPUTED_VALUE"""),45877.99861111111) -> 45877.999 | B13: =IFERROR(__xludf.DUMMYFUNCTION("""COMPUTED_VALUE"""),1.023829145E7) -> 10238291
A14: =IFERROR(__xludf.DUMMYFUNCTION("""COMPUTED_VALUE"""),45878.99861111111) -> 45878.999 | B14: =IFERROR(__xludf.DUMMYFUNCTION("""COMPUTED_VALUE"""),1.020261253E7) -> 10202613
A15: =IFERROR(__xludf.DUMMYFUNCTION("""COMPUTED_VALUE"""),45879.99861111111) -> 45879.999 | B15: =IFERROR(__xludf.DUMMYFUNCTION("""COMPUTED_VALUE"""),1.034390793E7) -> 10343908
A16: =IFERROR(__xludf.DUMMYFUNCTION("""COMPUTED_VALUE"""),45880.99861111111) -> 45880.999 | B16: =IFERROR(__xludf.DUMMYFUNCTION("""COMPUTED_VALUE"""),1.066534196E7) -> 10665342
A17: =IFERROR(__xludf.DUMMYFUNCTION("""COMPUTED_VALUE"""),45881.99861111111) -> 45881.999 | B17: =IFERROR(__xludf.DUMMYFUNCTION("""COMPUTED_VALUE"""),1.041064946E7) -> 10410649
A18: =IFERROR(__xludf.DUMMYFUNCTION("""COMPUTED_VALUE"""),45882.99861111111) -> 45882.999 | B18: =IFERROR(__xludf.DUMMYFUNCTION("""COMPUTED_VALUE"""),1.044524662E7) -> 10445247
A19: =IFERROR(__xludf.DUMMYFUNCTION("""COMPUTED_VALUE"""),45883.99861111111) -> 45883.999 | B19: =IFERROR(__xludf.DUMMYFUNCTION("""COMPUTED_VALUE"""),1.081520507E7) -> 10815205
A20: =IFERROR(__xludf.DUMMYFUNCTION("""COMPUTED_VALUE"""),45884.99861111111) -> 45884.999 | B20: =IFERROR(__xludf.DUMMYFUNCTION("""COMPUTED_VALUE"""),1.042063816E7) -> 10420638
A21: =IFERROR(__xludf.DUMMYFUNCTION("""COMPUTED_VALUE"""),45885.99861111111) -> 45885.999 | B21: =IFERROR(__xludf.DUMMYFUNCTION("""COMPUTED_VALUE"""),1.0287705E7) -> 10287705
A22: =IFERROR(__xludf.DUMMYFUNCTION("""COMPUTED_VALUE"""),45886.99861111111) -> 45886.999 | B22: =IFERROR(__xludf.DUMMYFUNCTION("""COMPUTED_VALUE"""),1.030838649E7) -> 10308386
A23: =IFERROR(__xludf.DUMMYFUNCTION("""COMPUTED_VALUE"""),45887.99861111111) -> 45887.999 | B23: =IFERROR(__xludf.DUMMYFUNCTION("""COMPUTED_VALUE"""),1.007526872E7) -> 10075269
A24: =IFERROR(__xludf.DUMMYFUNCTION("""COMPUTED_VALUE"""),45888.99861111111) -> 45888.999 | B24: =IFERROR(__xludf.DUMMYFUNCTION("""COMPUTED_VALUE"""),1.000809675E7) -> 10008097
A25: =IFERROR(__xludf.DUMMYFUNCTION("""COMPUTED_VALUE"""),45889.99861111111) -> 45889.999 | B25: =IFERROR(__xludf.DUMMYFUNCTION("""COMPUTED_VALUE"""),9882630.868) -> 9882630.9
A26: =IFERROR(__xludf.DUMMYFUNCTION("""COMPUTED_VALUE"""),45890.99861111111) -> 45890.999 | B26: =IFERROR(__xludf.DUMMYFUNCTION("""COMPUTED_VALUE"""),9951840.42) -> 9951840.4
A27: =IFERROR(__xludf.DUMMYFUNCTION("""COMPUTED_VALUE"""),45891.99861111111) -> 45891.999 | B27: =IFERROR(__xludf.DUMMYFUNCTION("""COMPUTED_VALUE"""),9863609.112) -> 9863609.1
A28: =IFERROR(__xludf.DUMMYFUNCTION("""COMPUTED_VALUE"""),45892.99861111111) -> 45892.999 | B28: =IFERROR(__xludf.DUMMYFUNCTION("""COMPUTED_VALUE"""),1.008385537E7) -> 10083855
A29: =IFERROR(__xludf.DUMMYFUNCTION("""COMPUTED_VALUE"""),45893.99861111111) -> 45893.999 | B29: =IFERROR(__xludf.DUMMYFUNCTION("""COMPUTED_VALUE"""),1.003601875E7) -> 10036019
A30: =IFERROR(__xludf.DUMMYFUNCTION("""COMPUTED_VALUE"""),45894.99861111111) -> 45894.999 | B30: =IFERROR(__xludf.DUMMYFUNCTION("""COMPUTED_VALUE"""),9903635.339) -> 9903635.3
A31: =IFERROR(__xludf.DUMMYFUNCTION("""COMPUTED_VALUE"""),45895.99861111111) -> 45895.999 | B31: =IFERROR(__xludf.DUMMYFUNCTION("""COMPUTED_VALUE"""),9629375.546) -> 9629375.5
A32: =IFERROR(__xludf.DUMMYFUNCTION("""COMPUTED_VALUE"""),45896.99861111111) -> 45896.999 | B32: =IFERROR(__xludf.DUMMYFUNCTION("""COMPUTED_VALUE"""),9772104.979) -> 9772105
A33: =IFERROR(__xludf.DUMMYFUNCTION("""COMPUTED_VALUE"""),45897.99861111111) -> 45897.999 | B33: =IFERROR(__xludf.DUMMYFUNCTION("""COMPUTED_VALUE"""),9813073.334) -> 9813073.3
A34: =IFERROR(__xludf.DUMMYFUNCTION("""COMPUTED_VALUE"""),45898.99861111111) -> 45898.999 | B34: =IFERROR(__xludf.DUMMYFUNCTION("""COMPUTED_VALUE"""),9854403.86) -> 9854403.9
A35: =IFERROR(__xludf.DUMMYFUNCTION("""COMPUTED_VALUE"""),45899.99861111111) -> 45899.999 | B35: =IFERROR(__xludf.DUMMYFUNCTION("""COMPUTED_VALUE"""),9562099.084) -> 9562099.1
A36: =IFERROR(__xludf.DUMMYFUNCTION("""COMPUTED_VALUE"""),45900.99861111111) -> 45900.999 | B36: =IFERROR(__xludf.DUMMYFUNCTION("""COMPUTED_VALUE"""),9633183.353) -> 9633183.4
A37: =IFERROR(__xludf.DUMMYFUNCTION("""COMPUTED_VALUE"""),45901.99861111111) -> 45901.999 | B37: =IFERROR(__xludf.DUMMYFUNCTION("""COMPUTED_VALUE"""),9477249.172) -> 9477249.2
A38: =IFERROR(__xludf.DUMMYFUNCTION("""COMPUTED_VALUE"""),45902.99861111111) -> 45902.999 | B38: =IFERROR(__xludf.DUMMYFUNCTION("""COMPUTED_VALUE"""),9712803.562) -> 9712803.6
A39: =IFERROR(__xludf.DUMMYFUNCTION("""COMPUTED_VALUE"""),45903.99861111111) -> 45903.999 | B39: =IFERROR(__xludf.DUMMYFUNCTION("""COMPUTED_VALUE"""),9784258.559) -> 9784258.6
A40: =IFERROR(__xludf.DUMMYFUNCTION("""COMPUTED_VALUE"""),45904.99861111111) -> 45904.999 | B40: =IFERROR(__xludf.DUMMYFUNCTION("""COMPUTED_VALUE"""),9806671.25) -> 9806671.2
...

Sheet Ethereum
A1: =IFERROR(__xludf.DUMMYFUNCTION("GOOGLEFINANCE(""CURRENCY:ETHINR"", ""price"", DATE(2025,7,28), DATE(2026,7,28), ""DAILY"")"),"Date") -> Date | B1: =IFERROR(__xludf.DUMMYFUNCTION("""COMPUTED_VALUE"""),"Close") -> Close
A2: =IFERROR(__xludf.DUMMYFUNCTION("""COMPUTED_VALUE"""),45866.99861111111) -> 45866.999 | B2: =IFERROR(__xludf.DUMMYFUNCTION("""COMPUTED_VALUE"""),336552.5302) -> 336552.53
A3: =IFERROR(__xludf.DUMMYFUNCTION("""COMPUTED_VALUE"""),45867.99861111111) -> 45867.999 | B3: =IFERROR(__xludf.DUMMYFUNCTION("""COMPUTED_VALUE"""),330099.5831) -> 330099.58
A4: =IFERROR(__xludf.DUMMYFUNCTION("""COMPUTED_VALUE"""),45868.99861111111) -> 45868.999 | B4: =IFERROR(__xludf.DUMMYFUNCTION("""COMPUTED_VALUE"""),334746.3224) -> 334746.32
A5: =IFERROR(__xludf.DUMMYFUNCTION("""COMPUTED_VALUE"""),45869.99861111111) -> 45869.999 | B5: =IFERROR(__xludf.DUMMYFUNCTION("""COMPUTED_VALUE"""),337732.4098) -> 337732.41
A6: =IFERROR(__xludf.DUMMYFUNCTION("""COMPUTED_VALUE"""),45870.99861111111) -> 45870.999 | B6: =IFERROR(__xludf.DUMMYFUNCTION("""COMPUTED_VALUE"""),322677.9475) -> 322677.95
A7: =IFERROR(__xludf.DUMMYFUNCTION("""COMPUTED_VALUE"""),45871.99861111111) -> 45871.999 | B7: =IFERROR(__xludf.DUMMYFUNCTION("""COMPUTED_VALUE"""),307248.7495) -> 307248.75
A8: =IFERROR(__xludf.DUMMYFUNCTION("""COMPUTED_VALUE"""),45872.99861111111) -> 45872.999 | B8: =IFERROR(__xludf.DUMMYFUNCTION("""COMPUTED_VALUE"""),300820.9161) -> 300820.92
A9: =IFERROR(__xludf.DUMMYFUNCTION("""COMPUTED_VALUE"""),45873.99861111111) -> 45873.999 | B9: =IFERROR(__xludf.DUMMYFUNCTION("""COMPUTED_VALUE"""),312879.84) -> 312879.84
A10: =IFERROR(__xludf.DUMMYFUNCTION("""COMPUTED_VALUE"""),45874.99861111111) -> 45874.999 | B10: =IFERROR(__xludf.DUMMYFUNCTION("""COMPUTED_VALUE"""),320445.9303) -> 320445.93
A11: =IFERROR(__xludf.DUMMYFUNCTION("""COMPUTED_VALUE"""),45875.99861111111) -> 45875.999 | B11: =IFERROR(__xludf.DUMMYFUNCTION("""COMPUTED_VALUE"""),314499.1537) -> 314499.15
A12: =IFERROR(__xludf.DUMMYFUNCTION("""COMPUTED_VALUE"""),45876.99861111111) -> 45876.999 | B12: =IFERROR(__xludf.DUMMYFUNCTION("""COMPUTED_VALUE"""),319390.4316) -> 319390.43
A13: =IFERROR(__xludf.DUMMYFUNCTION("""COMPUTED_VALUE"""),45877.99861111111) -> 45877.999 | B13: =IFERROR(__xludf.DUMMYFUNCTION("""COMPUTED_VALUE"""),345259.9645) -> 345259.96
A14: =IFERROR(__xludf.DUMMYFUNCTION("""COMPUTED_VALUE"""),45878.99861111111) -> 45878.999 | B14: =IFERROR(__xludf.DUMMYFUNCTION("""COMPUTED_VALUE"""),354996.0259) -> 354996.03
A15: =IFERROR(__xludf.DUMMYFUNCTION("""COMPUTED_VALUE"""),45879.99861111111) -> 45879.999 | B15: =IFERROR(__xludf.DUMMYFUNCTION("""COMPUTED_VALUE"""),370367.0371) -> 370367.04
A16: =IFERROR(__xludf.DUMMYFUNCTION("""COMPUTED_VALUE"""),45880.99861111111) -> 45880.999 | B16: =IFERROR(__xludf.DUMMYFUNCTION("""COMPUTED_VALUE"""),377305.563) -> 377305.56
A17: =IFERROR(__xludf.DUMMYFUNCTION("""COMPUTED_VALUE"""),45881.99861111111) -> 45881.999 | B17: =IFERROR(__xludf.DUMMYFUNCTION("""COMPUTED_VALUE"""),375366.377) -> 375366.38
A18: =IFERROR(__xludf.DUMMYFUNCTION("""COMPUTED_VALUE"""),45882.99861111111) -> 45882.999 | B18: =IFERROR(__xludf.DUMMYFUNCTION("""COMPUTED_VALUE"""),406065.9607) -> 406065.96
A19: =IFERROR(__xludf.DUMMYFUNCTION("""COMPUTED_VALUE"""),45883.99861111111) -> 45883.999 | B19: =IFERROR(__xludf.DUMMYFUNCTION("""COMPUTED_VALUE"""),418500.7413) -> 418500.74
A20: =IFERROR(__xludf.DUMMYFUNCTION("""COMPUTED_VALUE"""),45884.99861111111) -> 45884.999 | B20: =IFERROR(__xludf.DUMMYFUNCTION("""COMPUTED_VALUE"""),405772.6682) -> 405772.67
A21: =IFERROR(__xludf.DUMMYFUNCTION("""COMPUTED_VALUE"""),45885.99861111111) -> 45885.999 | B21: =IFERROR(__xludf.DUMMYFUNCTION("""COMPUTED_VALUE"""),388071.3678) -> 388071.37
A22: =IFERROR(__xludf.DUMMYFUNCTION("""COMPUTED_VALUE"""),45886.99861111111) -> 45886.999 | B22: =IFERROR(__xludf.DUMMYFUNCTION("""COMPUTED_VALUE"""),389854.6213) -> 389854.62
A23: =IFERROR(__xludf.DUMMYFUNCTION("""COMPUTED_VALUE"""),45887.99861111111) -> 45887.999 | B23: =IFERROR(__xludf.DUMMYFUNCTION("""COMPUTED_VALUE"""),377577.8487) -> 377577.85
A24: =IFERROR(__xludf.DUMMYFUNCTION("""COMPUTED_VALUE"""),45888.99861111111) -> 45888.999 | B24: =IFERROR(__xludf.DUMMYFUNCTION("""COMPUTED_VALUE"""),367326.074) -> 367326.07
A25: =IFERROR(__xludf.DUMMYFUNCTION("""COMPUTED_VALUE"""),45889.99861111111) -> 45889.999 | B25: =IFERROR(__xludf.DUMMYFUNCTION("""COMPUTED_VALUE"""),360291.0734) -> 360291.07
A26: =IFERROR(__xludf.DUMMYFUNCTION("""COMPUTED_VALUE"""),45890.99861111111) -> 45890.999 | B26: =IFERROR(__xludf.DUMMYFUNCTION("""COMPUTED_VALUE"""),374819.6488) -> 374819.65
A27: =IFERROR(__xludf.DUMMYFUNCTION("""COMPUTED_VALUE"""),45891.99861111111) -> 45891.999 | B27: =IFERROR(__xludf.DUMMYFUNCTION("""COMPUTED_VALUE"""),373507.7521) -> 373507.75
A28: =IFERROR(__xludf.DUMMYFUNCTION("""COMPUTED_VALUE"""),45892.99861111111) -> 45892.999 | B28: =IFERROR(__xludf.DUMMYFUNCTION("""COMPUTED_VALUE"""),409492.1567) -> 409492.16
A29: =IFERROR(__xludf.DUMMYFUNCTION("""COMPUTED_VALUE"""),45893.99861111111) -> 45893.999 | B29: =IFERROR(__xludf.DUMMYFUNCTION("""COMPUTED_VALUE"""),417666.5839) -> 417666.58
A30: =IFERROR(__xludf.DUMMYFUNCTION("""COMPUTED_VALUE"""),45894.99861111111) -> 45894.999 | B30: =IFERROR(__xludf.DUMMYFUNCTION("""COMPUTED_VALUE"""),413710.1049) -> 413710.1
A31: =IFERROR(__xludf.DUMMYFUNCTION("""COMPUTED_VALUE"""),45895.99861111111) -> 45895.999 | B31: =IFERROR(__xludf.DUMMYFUNCTION("""COMPUTED_VALUE"""),385625.8691) -> 385625.87
A32: =IFERROR(__xludf.DUMMYFUNCTION("""COMPUTED_VALUE"""),45896.99861111111) -> 45896.999 | B32: =IFERROR(__xludf.DUMMYFUNCTION("""COMPUTED_VALUE"""),403682.1386) -> 403682.14
A33: =IFERROR(__xludf.DUMMYFUNCTION("""COMPUTED_VALUE"""),45897.99861111111) -> 45897.999 | B33: =IFERROR(__xludf.DUMMYFUNCTION("""COMPUTED_VALUE"""),397723.6659) -> 397723.67
A34: =IFERROR(__xludf.DUMMYFUNCTION("""COMPUTED_VALUE"""),45898.99861111111) -> 45898.999 | B34: =IFERROR(__xludf.DUMMYFUNCTION("""COMPUTED_VALUE"""),395981.9738) -> 395981.97
A35: =IFERROR(__xludf.DUMMYFUNCTION("""COMPUTED_VALUE"""),45899.99861111111) -> 45899.999 | B35: =IFERROR(__xludf.DUMMYFUNCTION("""COMPUTED_VALUE"""),383713.1712) -> 383713.17
A36: =IFERROR(__xludf.DUMMYFUNCTION("""COMPUTED_VALUE"""),45900.99861111111) -> 45900.999 | B36: =IFERROR(__xludf.DUMMYFUNCTION("""COMPUTED_VALUE"""),395368.1937) -> 395368.19
A37: =IFERROR(__xludf.DUMMYFUNCTION("""COMPUTED_VALUE"""),45901.99861111111) -> 45901.999 | B37: =IFERROR(__xludf.DUMMYFUNCTION("""COMPUTED_VALUE"""),387497.2345) -> 387497.23
A38: =IFERROR(__xludf.DUMMYFUNCTION("""COMPUTED_VALUE"""),45902.99861111111) -> 45902.999 | B38: =IFERROR(__xludf.DUMMYFUNCTION("""COMPUTED_VALUE"""),384311.3548) -> 384311.35
A39: =IFERROR(__xludf.DUMMYFUNCTION("""COMPUTED_VALUE"""),45903.99861111111) -> 45903.999 | B39: =IFERROR(__xludf.DUMMYFUNCTION("""COMPUTED_VALUE"""),381735.3916) -> 381735.39
A40: =IFERROR(__xludf.DUMMYFUNCTION("""COMPUTED_VALUE"""),45904.99861111111) -> 45904.999 | B40: =IFERROR(__xludf.DUMMYFUNCTION("""COMPUTED_VALUE"""),387836.1958) -> 387836.2
...

Sheet Solana
A1: =IFERROR(__xludf.DUMMYFUNCTION("GOOGLEFINANCE(""CURRENCY:SOLINR"", ""price"", DATE(2025,7,28), DATE(2026,7,28), ""DAILY"")"),"Date") -> Date | B1: =IFERROR(__xludf.DUMMYFUNCTION("""COMPUTED_VALUE"""),"Close") -> Close
A2: =IFERROR(__xludf.DUMMYFUNCTION("""COMPUTED_VALUE"""),45866.99861111111) -> 45866.999 | B2: =IFERROR(__xludf.DUMMYFUNCTION("""COMPUTED_VALUE"""),16378.28273) -> 16378.283
A3: =IFERROR(__xludf.DUMMYFUNCTION("""COMPUTED_VALUE"""),45867.99861111111) -> 45867.999 | B3: =IFERROR(__xludf.DUMMYFUNCTION("""COMPUTED_VALUE"""),15901.19672) -> 15901.197
A4: =IFERROR(__xludf.DUMMYFUNCTION("""COMPUTED_VALUE"""),45868.99861111111) -> 45868.999 | B4: =IFERROR(__xludf.DUMMYFUNCTION("""COMPUTED_VALUE"""),15906.72693) -> 15906.727
A5: =IFERROR(__xludf.DUMMYFUNCTION("""COMPUTED_VALUE"""),45869.99861111111) -> 45869.999 | B5: =IFERROR(__xludf.DUMMYFUNCTION("""COMPUTED_VALUE"""),15546.93637) -> 15546.936
A6: =IFERROR(__xludf.DUMMYFUNCTION("""COMPUTED_VALUE"""),45870.99861111111) -> 45870.999 | B6: =IFERROR(__xludf.DUMMYFUNCTION("""COMPUTED_VALUE"""),15016.83161) -> 15016.832
A7: =IFERROR(__xludf.DUMMYFUNCTION("""COMPUTED_VALUE"""),45871.99861111111) -> 45871.999 | B7: =IFERROR(__xludf.DUMMYFUNCTION("""COMPUTED_VALUE"""),14188.62761) -> 14188.628
A8: =IFERROR(__xludf.DUMMYFUNCTION("""COMPUTED_VALUE"""),45872.99861111111) -> 45872.999 | B8: =IFERROR(__xludf.DUMMYFUNCTION("""COMPUTED_VALUE"""),13826.34723) -> 13826.347
A9: =IFERROR(__xludf.DUMMYFUNCTION("""COMPUTED_VALUE"""),45873.99861111111) -> 45873.999 | B9: =IFERROR(__xludf.DUMMYFUNCTION("""COMPUTED_VALUE"""),14235.40102) -> 14235.401
A10: =IFERROR(__xludf.DUMMYFUNCTION("""COMPUTED_VALUE"""),45874.99861111111) -> 45874.999 | B10: =IFERROR(__xludf.DUMMYFUNCTION("""COMPUTED_VALUE"""),14863.80206) -> 14863.802
A11: =IFERROR(__xludf.DUMMYFUNCTION("""COMPUTED_VALUE"""),45875.99861111111) -> 45875.999 | B11: =IFERROR(__xludf.DUMMYFUNCTION("""COMPUTED_VALUE"""),14401.45764) -> 14401.458
A12: =IFERROR(__xludf.DUMMYFUNCTION("""COMPUTED_VALUE"""),45876.99861111111) -> 45876.999 | B12: =IFERROR(__xludf.DUMMYFUNCTION("""COMPUTED_VALUE"""),14703.68496) -> 14703.685
A13: =IFERROR(__xludf.DUMMYFUNCTION("""COMPUTED_VALUE"""),45877.99861111111) -> 45877.999 | B13: =IFERROR(__xludf.DUMMYFUNCTION("""COMPUTED_VALUE"""),15386.3756) -> 15386.376
A14: =IFERROR(__xludf.DUMMYFUNCTION("""COMPUTED_VALUE"""),45878.99861111111) -> 45878.999 | B14: =IFERROR(__xludf.DUMMYFUNCTION("""COMPUTED_VALUE"""),15499.05034) -> 15499.05
A15: =IFERROR(__xludf.DUMMYFUNCTION("""COMPUTED_VALUE"""),45879.99861111111) -> 45879.999 | B15: =IFERROR(__xludf.DUMMYFUNCTION("""COMPUTED_VALUE"""),15763.45816) -> 15763.458
A16: =IFERROR(__xludf.DUMMYFUNCTION("""COMPUTED_VALUE"""),45880.99861111111) -> 45880.999 | B16: =IFERROR(__xludf.DUMMYFUNCTION("""COMPUTED_VALUE"""),16031.80323) -> 16031.803
A17: =IFERROR(__xludf.DUMMYFUNCTION("""COMPUTED_VALUE"""),45881.99861111111) -> 45881.999 | B17: =IFERROR(__xludf.DUMMYFUNCTION("""COMPUTED_VALUE"""),15325.9364) -> 15325.936
A18: =IFERROR(__xludf.DUMMYFUNCTION("""COMPUTED_VALUE"""),45882.99861111111) -> 45882.999 | B18: =IFERROR(__xludf.DUMMYFUNCTION("""COMPUTED_VALUE"""),16774.69398) -> 16774.694
A19: =IFERROR(__xludf.DUMMYFUNCTION("""COMPUTED_VALUE"""),45883.99861111111) -> 45883.999 | B19: =IFERROR(__xludf.DUMMYFUNCTION("""COMPUTED_VALUE"""),17683.46362) -> 17683.464
A20: =IFERROR(__xludf.DUMMYFUNCTION("""COMPUTED_VALUE"""),45884.99861111111) -> 45884.999 | B20: =IFERROR(__xludf.DUMMYFUNCTION("""COMPUTED_VALUE"""),16854.63803) -> 16854.638
A21: =IFERROR(__xludf.DUMMYFUNCTION("""COMPUTED_VALUE"""),45885.99861111111) -> 45885.999 | B21: =IFERROR(__xludf.DUMMYFUNCTION("""COMPUTED_VALUE"""),16258.8717) -> 16258.872
A22: =IFERROR(__xludf.DUMMYFUNCTION("""COMPUTED_VALUE"""),45886.99861111111) -> 45886.999 | B22: =IFERROR(__xludf.DUMMYFUNCTION("""COMPUTED_VALUE"""),16606.70021) -> 16606.7
A23: =IFERROR(__xludf.DUMMYFUNCTION("""COMPUTED_VALUE"""),45887.99861111111) -> 45887.999 | B23: =IFERROR(__xludf.DUMMYFUNCTION("""COMPUTED_VALUE"""),16687.78525) -> 16687.785
A24: =IFERROR(__xludf.DUMMYFUNCTION("""COMPUTED_VALUE"""),45888.99861111111) -> 45888.999 | B24: =IFERROR(__xludf.DUMMYFUNCTION("""COMPUTED_VALUE"""),15941.0919) -> 15941.092
A25: =IFERROR(__xludf.DUMMYFUNCTION("""COMPUTED_VALUE"""),45889.99861111111) -> 45889.999 | B25: =IFERROR(__xludf.DUMMYFUNCTION("""COMPUTED_VALUE"""),15326.05436) -> 15326.054
A26: =IFERROR(__xludf.DUMMYFUNCTION("""COMPUTED_VALUE"""),45890.99861111111) -> 45890.999 | B26: =IFERROR(__xludf.DUMMYFUNCTION("""COMPUTED_VALUE"""),16377.20206) -> 16377.202
A27: =IFERROR(__xludf.DUMMYFUNCTION("""COMPUTED_VALUE"""),45891.99861111111) -> 45891.999 | B27: =IFERROR(__xludf.DUMMYFUNCTION("""COMPUTED_VALUE"""),15744.17552) -> 15744.176
A28: =IFERROR(__xludf.DUMMYFUNCTION("""COMPUTED_VALUE"""),45892.99861111111) -> 45892.999 | B28: =IFERROR(__xludf.DUMMYFUNCTION("""COMPUTED_VALUE"""),17522.86929) -> 17522.869
A29: =IFERROR(__xludf.DUMMYFUNCTION("""COMPUTED_VALUE"""),45893.99861111111) -> 45893.999 | B29: =IFERROR(__xludf.DUMMYFUNCTION("""COMPUTED_VALUE"""),17810.70317) -> 17810.703
A30: =IFERROR(__xludf.DUMMYFUNCTION("""COMPUTED_VALUE"""),45894.99861111111) -> 45894.999 | B30: =IFERROR(__xludf.DUMMYFUNCTION("""COMPUTED_VALUE"""),18033.41555) -> 18033.416
A31: =IFERROR(__xludf.DUMMYFUNCTION("""COMPUTED_VALUE"""),45895.99861111111) -> 45895.999 | B31: =IFERROR(__xludf.DUMMYFUNCTION("""COMPUTED_VALUE"""),16406.93658) -> 16406.937
A32: =IFERROR(__xludf.DUMMYFUNCTION("""COMPUTED_VALUE"""),45896.99861111111) -> 45896.999 | B32: =IFERROR(__xludf.DUMMYFUNCTION("""COMPUTED_VALUE"""),17173.09266) -> 17173.093
A33: =IFERROR(__xludf.DUMMYFUNCTION("""COMPUTED_VALUE"""),45897.99861111111) -> 45897.999 | B33: =IFERROR(__xludf.DUMMYFUNCTION("""COMPUTED_VALUE"""),17776.13113) -> 17776.131
A34: =IFERROR(__xludf.DUMMYFUNCTION("""COMPUTED_VALUE"""),45898.99861111111) -> 45898.999 | B34: =IFERROR(__xludf.DUMMYFUNCTION("""COMPUTED_VALUE"""),18904.29965) -> 18904.3
A35: =IFERROR(__xludf.DUMMYFUNCTION("""COMPUTED_VALUE"""),45899.99861111111) -> 45899.999 | B35: =IFERROR(__xludf.DUMMYFUNCTION("""COMPUTED_VALUE"""),18088.2271) -> 18088.227
A36: =IFERROR(__xludf.DUMMYFUNCTION("""COMPUTED_VALUE"""),45900.99861111111) -> 45900.999 | B36: =IFERROR(__xludf.DUMMYFUNCTION("""COMPUTED_VALUE"""),17885.94513) -> 17885.945
A37: =IFERROR(__xludf.DUMMYFUNCTION("""COMPUTED_VALUE"""),45901.99861111111) -> 45901.999 | B37: =IFERROR(__xludf.DUMMYFUNCTION("""COMPUTED_VALUE"""),17676.67401) -> 17676.674
A38: =IFERROR(__xludf.DUMMYFUNCTION("""COMPUTED_VALUE"""),45902.99861111111) -> 45902.999 | B38: =IFERROR(__xludf.DUMMYFUNCTION("""COMPUTED_VALUE"""),17347.09607) -> 17347.096
A39: =IFERROR(__xludf.DUMMYFUNCTION("""COMPUTED_VALUE"""),45903.99861111111) -> 45903.999 | B39: =IFERROR(__xludf.DUMMYFUNCTION("""COMPUTED_VALUE"""),18450.80909) -> 18450.809
A40: =IFERROR(__xludf.DUMMYFUNCTION("""COMPUTED_VALUE"""),45904.99861111111) -> 45904.999 | B40: =IFERROR(__xludf.DUMMYFUNCTION("""COMPUTED_VALUE"""),18587.24456) -> 18587.245
...

Sheet Summary
A1: Asset | B1: Starting Price (INR) | C1: Ending Price (INR) | D1: 1-Year Return (%) | E1: 52-Week High (INR) | F1: 52-Week Low (INR)
A2: Bitcoin | B2: =Bitcoin!B2 -> 10351153 | C2: {=INDEX(Bitcoin!B:B, COUNTA(Bitcoin!B:B))} -> 6247126.2 | D2: =(C2-B2)/B2 -> -0.39648017 | E2: =MAX(Bitcoin!B2:B1000) -> 11031646 | F2: =MIN(Bitcoin!B2:B1000) -> 5639316.4
A3: Ethereum | B3: =Ethereum!B2 -> 336552.53 | C3: {=INDEX(Ethereum!B:B, COUNTA(Ethereum!B:B))} -> 186476.72 | D3: =(C3-B3)/B3 -> -0.44592092 | E3: =MAX(Ethereum!B2:B1000) -> 419789.14 | F3: =MIN(Ethereum!B2:B1000) -> 146702.79
A4: Solana | B4: =Solana!B2 -> 16378.283 | C4: {=INDEX(Solana!B:B, COUNTA(Solana!B:B))} -> 7337.5603 | D4: =(C4-B4)/B4 -> -0.55199453 | E4: =MAX(Solana!B2:B1000) -> 21815.443 | F4: =MIN(Solana!B2:B1000) -> 5904.5983
